tests/32_threads/sample_89.in
32
o
20 S 101 1 1856 490
2 S 102 7 1905 586
4 B 103 0 1575 520
25 B 104 3 1731 968
24 S 105 6 1595 18
22 S 107 8 1505 43
12 B 108 3 1117 906
1 S 109 4 1201 568
9 B 110 1 1429 461
17 S 111 8 1145 518
2 B 112 9 1375 362
14 B 113 9 1688 959
26 S 115 7 1574 12
29 B 116 8 1918 123
20 B 117 4 1008 536
4 S 118 7 1488 545
11 S 122 0 1264 750
25 C 104
17 C 111
9 S 125 4 1409 315
7 S 126 0 1875 185
14 S 127 7 1728 77
14 S 128 5 1557 835
3 B 130 2 1240 586
8 B 131 7 1225 258
21 S 132 3 1914 964
4 S 133 6 1450 741
1 B 134 7 1656 702
1 S 135 1 1136 674
8 B 136 6 1144 669
25 C 104
14 B 138 4 1801 516
24 B 139 9 1752 877
4 B 140 6 1245 223
28 B 142 7 1474 913
29 C 116
10 S 144 4 1498 933
31 S 145 8 1711 24
29 S 146 1 1751 272
4 S 147 3 1727 914
26 S 148 1 1819 570
7 B 149 2 1301 904
5 S 150 2 1984 515
11 B 151 4 1764 851
26 B 153 6 1060 402
2 S 155 0 1259 969
21 S 157 8 1688 829
24 S 158 2 1886 99
17 B 159 6 1401 282
13 B 161 9 1360 118
21 B 162 5 1312 471
21 C 132
2 S 164 7 1585 22
11 C 151
2 S 166 2 1648 236
20 C 117
5 C 150
0 S 169 3 1582 639
12 C 108
21 S 171 1 1696 746
20 C 117
26 B 173 5 1597 188
5 S 174 3 1391 230
3 S 175 3 1291 282
20 C 101
28 B 178 7 1534 951
13 B 179 5 1943 647
23 S 180 0 1833 728
16 S 182 6 1703 704
7 B 183 6 1887 754
26 C 173
1 S 185 0 1698 554
12 C 108
9 B 187 2 1419 517
12 C 108
31 B 189 6 1105 888
28 C 178
12 S 191 5 1494 828
26 C 173
7 B 194 8 1708 143
16 B 195 3 1280 333
11 C 151
7 B 197 8 1669 679
16 B 198 7 1200 20
4 S 199 8 1381 307
11 B 200 0 1523 191
4 C 118
21 B 203 2 1344 676
28 S 204 2 1691 230
8 S 206 2 1703 584
7 B 207 4 1485 715
28 B 208 4 1269 745
11 B 209 3 1852 382
6 B 210 8 1270 590
25 C 104
20 B 212 7 1398 277
6 S 213 7 1641 628
2 B 214 7 1100 978
6 C 210
20 B 216 0 1239 388
25 B 217 4 1887 961
3 C 175
25 C 104
21 S 220 4 1760 376
26 C 153
6 B 222 3 1216 924
22 C 107
15 S 224 0 1656 879
4 B 225 5 1458 447
5 S 226 9 1280 376
27 S 227 5 1311 479
5 B 228 6 1738 444
29 S 229 1 1239 833
22 S 230 5 1835 348
15 C 224
5 S 232 5 1539 890
13 B 233 1 1383 711
14 B 235 5 1342 507
14 C 127
23 B 237 0 1823 836
9 C 125
5 B 239 6 1743 110
20 B 240 4 1081 236
10 S 241 7 1502 295
4 C 140
3 S 243 3 1594 905
6 B 244 4 1406 793
2 S 245 3 1137 1000
20 S 246 7 1751 232
0 B 247 5 1117 745
27 C 227
10 B 249 6 1133 242
0 C 247
25 C 217
30 B 252 4 1313 390
22 B 253 3 1555 938
10 B 254 8 1957 360
28 S 255 0 1655 660
8 B 256 8 1339 662
28 B 257 2 1672 915
30 B 258 2 1296 510
27 S 259 2 1349 274
9 B 260 5 1384 17
10 B 261 1 1837 677
15 B 262 9 1153 300
0 C 169
31 C 189
13 C 233
6 S 266 8 1583 990
1 C 135
28 C 204
19 S 269 7 1770 328
0 C 169
10 C 144
2 S 272 0 1826 551
13 B 273 7 1497 227
21 S 274 0 1547 776
30 S 275 2 1583 454
0 B 276 1 1060 925
28 B 277 7 1657 842
9 S 278 6 1621 95
29 C 146
30 S 280 5 1476 100
22 B 281 3 1799 444
20 C 246
28 S 283 2 1182 418
17 C 159
12 B 285 4 1300 615
29 C 116
2 C 112
6 C 244
5 C 228
19 C 269
17 S 291 7 1737 141
5 S 292 2 1614 863
17 S 293 4 1273 466
4 B 294 6 1429 407
26 S 295 9 1344 11
29 C 116
7 B 297 1 1994 609
8 C 136
5 C 174
7 S 300 4 1769 39
16 B 301 3 1502 722
13 S 302 3 1970 833
8 B 303 3 1682 229
25 C 217
5 C 292
29 S 306 0 1641 248
9 B 307 1 1499 505
27 S 308 1 1749 487
8 C 256
8 B 310 3 1931 414
12 B 311 7 1928 624
14 B 312 7 1895 432
11 B 313 9 1865 604
25 S 314 5 1964 816
1 B 315 1 1305 871
21 C 157
30 B 317 0 1707 600
2 C 245
7 C 300
22 S 320 7 1382 189
13 S 322 1 1675 816
4 S 323 8 1210 417
8 B 324 0 1794 730
9 B 325 7 1134 883
10 C 144
14 C 113
30 B 328 2 1319 848
23 B 329 6 1524 123
20 C 212
12 S 331 8 1740 63
21 B 332 4 1274 771
1 B 333 2 1756 418
16 C 195
18 B 335 6 1780 737
0 S 336 5 1520 380
24 B 337 9 1684 237
6 S 338 8 1279 409
8 C 324
25 C 217
12 B 341 5 1091 967
12 S 342 2 1024 43
16 S 343 5 1405 709
15 C 224
18 S 345 8 1564 432
11 B 346 4 1693 391
16 S 347 0 1910 275
28 C 142
29 C 229
0 C 276
3 B 351 9 1040 179
14 B 352 9 1741 405
10 S 353 3 1541 101
30 S 354 0 1794 583
13 S 355 1 1653 375
28 C 277
3 S 357 8 1336 19
14 S 358 1 1456 240
8 B 359 4 1024 502
0 B 360 3 1948 287
2 C 112
29 S 362 8 1492 856
8 C 136
13 C 161
27 S 365 8 1485 488
17 C 291
5 C 232
8 C 206
1 S 369 6 1588 148
0 B 370 8 1682 227
2 C 214
14 S 372 1 1977 849
28 B 373 6 1950 655
13 S 374 5 1154 761
29 C 229
2 B 376 3 1767 882
7 B 377 9 1505 672
0 B 378 5 1279 322
10 S 379 4 1161 469
12 C 331
23 C 329
3 C 351
11 B 383 7 1107 161
25 S 384 2 1546 771
28 B 385 8 1691 459
5 S 386 2 1634 696
11 B 387 2 1460 574
8 S 388 7 1568 93
21 S 389 7 1284 177
9 C 125
18 B 391 0 1806 194
1 S 392 7 1243 936
25 C 314
27 B 394 6 1505 114
23 B 395 1 1184 566
3 B 396 0 1954 266
22 S 397 6 1768 521
30 C 328
11 S 399 9 1308 72
9 B 400 4 1129 669
5 C 292
5 B 402 3 1659 47
7 C 197
26 S 404 2 1791 912
20 C 117
12 S 406 8 1917 503
16 C 301
10 B 408 0 1798 185
30 C 258
4 S 410 5 1601 641
13 S 411 0 1248 778
11 C 209
10 C 144
3 C 396
5 C 232
8 C 136
26 C 404
29 S 418 1 1400 633
13 B 419 7 1164 831
28 C 283
27 S 421 7 1532 835
21 S 422 9 1445 621
29 B 423 1 1205 87
5 B 424 1 1300 927
31 C 145
7 S 426 9 1627 752
9 S 427 9 1741 249
29 C 116
3 C 243
24 B 430 4 1633 488
6 B 431 3 1293 295
13 B 432 6 1149 856
22 S 433 0 1123 194
13 B 434 5 1085 204
15 S 435 7 1435 190
6 S 436 2 1652 286
10 B 437 0 1721 418
20 S 438 1 1273 305
9 B 439 9 1282 995
21 B 440 2 1804 225
1 B 441 0 1100 200
16 B 442 8 1487 536
18 S 443 8 1007 28
25 C 384
1 S 445 1 1131 538
30 S 446 3 1118 254
20 S 447 1 1952 90
0 B 448 8 1821 773
12 C 108
18 S 450 9 1037 21
4 S 451 6 1433 34
0 C 247
11 C 200
18 C 391
15 S 455 9 1053 990
17 C 291
28 C 178
0 S 458 9 1505 257
30 S 459 2 1163 466
13 C 411
26 C 404
9 C 260
29 S 463 1 1354 314
19 S 464 7 1150 635
3 C 351
17 C 111
24 C 158
8 C 359
8 S 469 0 1768 827
1 B 470 3 1052 374
4 S 471 8 1498 383
0 B 472 7 1131 344
21 C 171
30 C 252
0 C 276
1 B 476 6 1994 737
10 B 477 0 1441 644
21 B 478 3 1568 544
11 C 122
17 C 293
5 C 292
8 B 482 3 1219 208
15 B 483 4 1331 283
8 B 484 2 1694 325
15 S 485 9 1637 129
3 B 486 7 1428 173
31 S 487 8 1960 715
18 C 391
1 S 489 3 1545 563
27 B 490 0 1870 549
22 C 281
8 S 492 9 1778 403
30 S 493 6 1421 228
13 S 494 9 1231 682
15 C 224
19 C 464
5 C 232
18 C 335
21 B 499 0 1551 295
7 C 183
3 C 351
21 S 502 0 1248 913
31 S 503 2 1500 284
1 B 504 9 1760 40
3 S 505 3 1605 462
13 S 506 8 1914 162
14 C 372
1 B 508 4 1170 583
3 B 509 3 1220 79
18 B 510 8 1608 965
5 B 511 2 1306 566
9 C 278
18 C 345
19 C 464
26 B 515 2 1516 693
23 C 329
9 B 517 0 1845 446
1 B 518 7 1667 946
8 B 519 5 1174 573
23 C 395
21 B 521 8 1579 716
13 S 522 5 1376 922
14 S 523 3 1267 646
4 C 140
12 S 525 5 1365 160
13 B 526 6 1149 22
25 B 527 7 1099 386
31 S 528 3 1195 53
3 B 529 8 1084 514
13 B 530 4 1305 307
6 S 531 6 1161 22
1 S 532 4 1002 633
9 B 533 8 1410 326
17 S 534 1 1249 636
30 B 535 1 1104 166
0 C 370
14 B 537 2 1160 148
2 C 214
28 C 204
15 S 540 4 1260 20
4 B 541 7 1186 926
2 B 542 4 1675 371
7 B 543 1 1047 810
16 C 182
21 C 478
5 S 546 1 1979 152
22 B 547 8 1611 190
23 C 329
4 B 549 9 1134 754
19 C 269
18 S 551 0 1249 845
25 B 552 9 1110 883
11 C 399
13 S 554 2 1044 86
16 S 555 7 1733 882
4 C 541
22 B 557 5 1640 328
19 C 269
8 C 359
7 S 560 0 1924 361
0 S 561 5 1626 560
11 B 562 5 1890 186
4 C 147
2 S 564 7 1959 604
31 C 528
26 C 404
8 S 567 6 1628 248
17 S 568 1 1368 449
1 S 569 5 1149 869
19 C 269
5 S 571 0 1565 44
28 C 204
15 S 573 1 1954 594
5 S 574 7 1796 310
13 B 575 6 1891 155
16 B 576 2 1432 928
21 B 577 0 1227 220
5 C 574
6 B 579 3 1429 872
4 B 580 8 1288 553
6 B 581 0 1392 583
11 C 151
21 B 583 6 1002 829
10 C 241
8 C 136
18 C 335
7 C 194
7 C 300
6 B 589 8 1849 536
22 B 590 9 1342 47
0 B 591 6 1482 921
28 C 204
16 B 593 8 1693 431
28 S 594 5 1487 956
8 C 303
5 C 424
14 C 352
20 C 246
3 S 599 9 1903 210
30 B 600 4 1253 724
8 S 601 6 1194 708
18 S 602 5 1007 21
21 B 603 8 1387 387
13 S 604 2 1703 136
24 C 139
30 B 606 3 1937 980
0 C 276
27 B 608 0 1262 194
12 S 609 3 1886 437
12 C 108
20 C 212
2 C 102
11 C 346
16 B 614 4 1369 833
29 C 116
19 C 464
2 S 617 2 1930 914
6 S 618 5 1298 68
22 S 619 1 1226 253
2 B 620 1 1669 26
26 B 621 0 1481 258
