tests/32_threads/sample_9.in
32
o
28 S 101 1 1928 685
5 S 103 6 1477 658
0 B 104 9 1915 421
5 S 106 2 1535 699
2 S 108 9 1078 607
5 S 109 4 1060 417
20 B 110 5 1351 409
28 S 111 4 1348 765
25 B 112 8 1745 836
1 S 113 6 1014 125
31 S 115 9 1302 100
11 B 116 5 1831 580
17 S 117 0 1396 743
13 B 118 9 1635 762
25 B 119 3 1016 79
16 S 120 6 1032 430
6 B 121 5 1423 222
5 S 122 6 1853 987
20 S 124 3 1856 616
28 B 127 6 1071 264
25 C 119
17 C 117
28 C 127
15 S 131 2 1378 903
16 C 120
10 B 133 8 1287 45
25 C 119
17 S 135 3 1926 633
25 C 119
22 B 137 4 1002 834
18 B 138 1 1335 236
31 B 139 9 1864 454
31 S 141 5 1210 635
5 C 122
27 S 143 1 1998 551
10 B 144 7 1050 262
31 S 146 3 1218 456
27 C 143
30 S 149 0 1430 765
4 S 151 9 1798 370
8 S 152 6 1519 250
20 S 153 6 1958 767
0 S 154 5 1893 522
23 B 155 8 1114 160
11 B 156 0 1920 926
11 S 157 3 1777 197
29 S 158 8 1603 729
4 B 159 0 1559 889
6 B 160 5 1933 41
18 S 161 6 1153 996
1 S 162 6 1711 478
3 S 163 2 1764 830
27 C 143
8 C 152
10 B 166 9 1952 486
8 C 152
13 S 168 1 1538 151
31 C 146
14 S 170 0 1176 641
12 B 171 4 1293 827
25 S 172 0 1389 162
8 S 173 9 1960 935
4 S 174 7 1272 99
27 S 175 0 1320 331
7 S 176 1 1960 137
14 B 177 3 1529 583
22 C 137
13 C 118
3 C 163
5 S 181 6 1993 942
5 S 182 4 1185 23
21 S 183 6 1120 695
24 B 184 8 1221 785
6 S 185 0 1461 177
27 B 186 1 1853 285
1 S 187 2 1237 586
27 S 188 7 1254 679
25 S 189 3 1301 502
16 C 120
20 S 191 6 1612 797
3 C 163
4 B 193 9 1692 931
25 B 194 7 1016 848
21 B 195 3 1093 796
11 S 196 6 1266 831
13 B 197 5 1491 261
4 B 198 2 1084 820
6 S 200 3 1274 996
27 C 143
17 C 135
15 C 131
2 B 204 0 1729 560
5 S 205 0 1066 23
6 C 185
0 B 207 2 1906 256
14 S 208 8 1893 544
16 C 120
7 S 210 5 1792 99
17 B 211 0 1273 312
31 C 141
7 B 213 4 1512 84
11 B 214 8 1502 170
0 S 215 6 1464 59
17 S 216 1 1691 496
1 B 217 6 1546 557
16 C 120
12 B 219 6 1420 268
19 S 220 5 1347 814
15 S 221 1 1187 915
8 B 222 9 1137 667
25 B 223 5 1855 965
8 C 152
18 C 138
0 C 207
21 B 227 2 1529 703
12 C 171
11 S 229 9 1974 714
30 C 149
4 S 231 6 1193 451
12 S 232 7 1503 452
24 S 233 0 1121 958
25 B 234 3 1916 240
11 S 235 8 1016 538
18 C 138
29 S 237 3 1777 88
11 S 238 6 1873 129
17 C 211
24 C 184
10 C 133
12 B 242 7 1105 90
4 C 231
0 C 104
17 C 211
19 C 220
2 B 248 6 1883 165
28 S 249 1 1762 901
31 B 250 7 1189 878
25 C 172
29 B 252 4 1317 226
6 S 253 8 1088 531
26 B 254 0 1003 573
8 B 255 3 1039 547
16 S 256 3 1177 625
29 S 257 6 1606 371
7 S 258 8 1424 381
1 B 259 0 1133 187
9 B 260 4 1353 819
29 B 261 7 1965 550
10 C 133
4 B 263 9 1244 248
22 B 264 4 1632 813
5 C 122
9 S 266 2 1401 511
25 S 267 3 1230 828
19 S 268 2 1615 257
23 C 155
21 S 270 4 1716 610
3 B 271 7 1166 969
24 C 233
8 S 273 2 1202 455
22 S 274 5 1657 940
15 B 275 3 1335 57
3 S 276 4 1258 990
21 S 277 7 1141 47
16 B 278 6 1525 933
17 C 211
26 C 254
31 B 281 8 1535 511
6 S 282 3 1305 140
9 C 260
14 C 208
30 B 285 6 1539 993
26 B 286 3 1678 702
17 S 287 5 1051 974
24 S 288 0 1974 872
30 B 289 7 1887 569
24 C 233
17 S 291 6 1096 79
10 C 133
30 C 149
7 C 176
12 B 295 5 1996 235
3 C 271
0 B 297 1 1903 802
30 B 298 6 1416 12
7 C 210
13 C 168
6 S 301 8 1065 886
10 S 302 2 1611 473
7 S 303 2 1307 328
9 C 260
21 C 183
12 S 306 4 1648 735
2 S 307 7 1225 826
8 C 273
4 S 309 8 1358 488
23 B 310 2 1752 257
15 C 221
0 S 312 3 1579 70
25 B 313 7 1792 251
16 C 120
6 C 200
8 C 222
26 S 317 9 1210 195
18 C 161
15 S 319 8 1711 507
3 B 320 6 1232 582
22 S 321 3 1794 75
7 B 322 2 1808 520
6 B 323 6 1962 798
31 C 250
14 S 325 9 1564 887
13 B 326 0 1552 547
30 B 327 9 1986 643
30 C 285
29 C 158
8 B 330 5 1752 42
29 C 252
6 C 185
25 B 333 9 1338 469
3 B 334 1 1172 568
21 C 183
9 S 336 3 1335 927
31 B 337 4 1910 606
29 B 338 3 1939 570
0 C 154
27 B 340 7 1685 425
4 C 151
29 B 342 5 1480 19
3 S 343 8 1250 57
30 S 344 8 1440 406
0 B 345 0 1474 58
12 C 171
13 C 118
22 C 264
22 S 349 1 1635 349
9 C 266
30 C 289
1 C 217
1 S 353 7 1682 90
25 C 189
26 S 355 8 1018 563
25 S 356 4 1547 338
18 C 138
3 C 271
3 S 359 9 1159 46
13 S 360 8 1500 591
31 C 146
5 B 362 5 1518 633
1 S 363 1 1836 751
15 S 364 3 1403 708
16 B 365 3 1866 523
1 C 113
22 S 367 2 1263 992
30 B 368 7 1671 638
6 B 369 4 1935 882
12 B 370 5 1228 545
23 C 155
21 B 372 8 1893 908
21 B 373 6 1685 56
24 B 374 9 1979 984
1 C 259
25 B 376 1 1246 755
5 S 377 1 1887 13
7 C 258
6 C 160
4 S 380 6 1837 640
24 S 381 6 1839 343
29 S 382 3 1017 120
21 B 383 7 1117 223
13 B 384 5 1333 578
12 B 385 1 1392 93
1 B 386 8 1518 341
17 C 211
21 B 388 9 1931 393
16 B 389 7 1550 799
6 C 121
18 C 138
30 C 344
20 S 393 8 1272 793
6 C 282
19 C 268
20 C 124
10 S 397 9 1296 518
31 B 398 3 1115 284
26 C 286
22 C 367
6 B 401 1 1095 564
6 B 402 2 1686 766
18 C 161
14 S 404 1 1601 834
1 S 405 7 1609 907
21 S 406 3 1581 211
15 S 407 5 1363 416
10 C 302
3 B 409 4 1829 811
28 S 410 5 1570 44
5 B 411 7 1658 148
6 S 412 1 1135 948
2 C 307
20 S 414 7 1255 845
28 B 415 2 1202 14
6 S 416 0 1406 468
0 S 417 7 1488 311
5 C 106
22 B 419 4 1772 158
29 B 420 4 1169 907
26 B 421 7 1738 94
28 B 422 6 1866 189
21 B 423 7 1818 635
23 S 424 5 1456 404
12 C 306
15 S 426 1 1440 285
10 S 427 3 1980 752
11 B 428 2 1666 300
1 C 187
9 C 266
25 B 431 0 1869 977
7 B 432 9 1278 801
12 S 433 5 1149 831
30 S 434 4 1123 216
17 C 135
12 B 436 4 1207 391
17 C 117
7 C 213
27 C 143
29 C 382
22 S 441 7 1706 414
28 B 442 0 1730 613
11 B 443 0 1602 827
14 S 444 5 1525 261
9 S 445 1 1059 574
20 S 446 1 1666 837
5 S 447 8 1819 808
2 B 448 3 1513 772
1 C 405
3 B 450 6 1678 19
27 B 451 1 1808 907
10 C 302
17 S 453 7 1544 672
14 B 454 4 1451 305
7 S 455 4 1801 320
17 S 456 0 1717 178
27 B 457 2 1134 752
27 C 188
5 B 459 8 1422 684
31 B 460 0 1830 333
21 S 461 2 1245 613
11 C 156
27 S 463 9 1996 114
18 S 464 4 1882 758
16 C 256
29 B 466 1 1423 76
28 B 467 5 1775 434
9 C 445
8 B 469 5 1755 335
23 B 470 2 1553 348
27 C 143
26 C 355
22 B 473 6 1653 523
6 S 474 2 1678 366
5 B 475 2 1274 21
18 B 476 5 1953 774
13 B 477 9 1189 868
26 B 478 0 1918 929
19 S 479 9 1577 595
14 C 404
2 C 204
24 S 482 8 1481 79
22 C 473
26 C 421
22 S 485 3 1189 671
5 B 486 9 1881 643
17 S 487 8 1918 295
15 B 488 7 1885 845
5 S 489 3 1119 765
31 S 490 0 1912 167
5 B 491 2 1612 59
14 S 492 4 1742 372
4 C 198
2 S 494 2 1326 50
2 C 494
27 S 496 3 1916 204
20 S 497 4 1972 796
1 C 353
22 C 264
23 B 500 0 1305 980
30 S 501 2 1613 911
26 C 317
31 S 503 0 1931 915
3 B 504 3 1587 884
15 B 505 3 1697 634
27 C 186
6 C 160
20 B 508 1 1236 825
22 S 509 7 1761 628
19 B 510 5 1396 662
13 B 511 3 1964 105
28 B 512 0 1099 276
2 B 513 2 1808 902
17 S 514 1 1187 937
15 B 515 6 1292 817
20 C 124
29 C 382
0 C 312
0 S 519 6 1217 406
3 S 520 4 1467 973
22 S 521 2 1398 889
25 C 376
9 C 445
24 C 381
21 B 525 3 1490 609
27 C 188
7 B 527 1 1453 578
17 B 528 3 1428 562
24 C 374
11 C 229
11 S 531 3 1741 546
26 B 532 4 1720 471
21 S 533 7 1269 351
18 S 534 2 1294 440
25 B 535 4 1135 609
4 B 536 2 1876 747
25 B 537 5 1382 591
3 B 538 4 1400 818
7 B 539 2 1357 880
1 B 540 2 1569 740
22 S 541 0 1611 912
0 B 542 1 1448 357
2 S 543 9 1791 307
31 C 490
22 B 545 2 1501 869
5 B 546 6 1662 15
31 S 547 3 1943 639
12 B 548 4 1365 663
7 B 549 6 1676 897
1 C 386
27 S 551 3 1748 488
14 C 454
2 S 553 4 1773 660
27 B 554 0 1774 558
13 C 511
7 S 556 9 1212 246
7 C 549
19 S 558 6 1543 906
27 C 188
4 C 174
4 C 193
12 C 433
19 B 563 6 1355 578
18 C 534
12 S 565 8 1893 678
7 S 566 7 1394 677
24 C 233
7 S 568 2 1021 540
2 S 569 1 1324 761
13 S 570 9 1308 575
28 B 571 2 1430 929
11 B 572 2 1641 765
27 B 573 1 1825 801
6 B 574 7 1634 151
30 B 575 5 1350 864
3 B 576 9 1637 553
24 B 577 0 1165 98
22 B 578 4 1413 189
5 C 491
2 B 580 5 1675 698
26 S 581 9 1524 859
31 S 582 2 1068 211
22 C 419
14 S 584 3 1718 838
3 C 504
6 S 586 5 1346 205
6 B 587 5 1423 965
0 S 588 1 1230 655
28 S 589 0 1400 658
8 S 590 0 1382 741
6 C 474
2 C 248
11 B 593 7 1188 693
13 C 118
25 C 189
24 B 596 6 1844 387
1 B 597 0 1919 603
28 S 598 7 1264 377
24 B 599 0 1670 315
1 S 600 9 1748 383
5 S 601 2 1746 209
24 C 577
18 S 603 4 1000 889
27 S 604 9 1811 463
12 B 605 8 1914 799
16 B 606 1 1934 686
29 B 607 0 1544 592
